## 오류란?
- 컴파일 오류(compile error) : 프로그램 코드 작성 중 발생하는 문법적 오류.
- 실행 오류(runtime error) : 실행 중인 프로그램이 의도 하지 않은 동작을 하거나(but) 프로그램이 중지되는 오류.
- 실행 오류 시 비정상 종류는 서비스 운영에 치명적.
- 오류가 발생할 수 있는 경우에 로그(log)를 남겨 추후 이를 분석하여 원인을 찾아야 함.
- 자바는 예외 처리를 통하여 프로그램의 비정상 종료를 막고 log를 남길 수 있음

## 오류와 예외 클래스
- 시스템 오류(error): 가상 머신에서 발생, 프로그래머가 처리 할 수 없음.   
  ex) 동적 메모리가 없는 경우, 스택 오버 플로우 등
- 예외(Exception) : 프로그램에서 제어 할 수 있는 오류.   
  ex) 읽어 들이려는 파일이 존재하지 않는 경우, 네트웍 연결이 끊어진 경우.

<code>
  <pre>
  package exception;


public class ArrayExceptionTest {

	public static void main(String[] args) {
		
		int[] arr = {1, 2, 3, 4, 5};
		
		for(int i = 0; i <= 5; i++) {
			System.out.println(arr[i]);
			}
			System.out.println("end");
	}
}
------------------출력------------------
1
2
3
4
5
Exception in thread "main" java.lang.ArrayIndexOutOfBoundsException: Index 5 out of bounds for length 5
	at Chapter14/exception.ArrayExceptionTest.main(ArrayExceptionTest.java:11)

이렇게 시스템적으로 죽었다고하면 마지막 값은 출력하지않음.
(end 안나옴)
</code>
  </pre>
  
  
## try - catch - fianlly 문
  
<code>
  <pre>
  package exception;

public class ArrayExceptionTest {

	public static void main(String[] args) {
		
		int[] arr = {1, 2, 3, 4, 5};
		try {
		for(int i = 0; i <= 5; i++) {
			System.out.println(arr[i]);
			}
		} catch(ArrayIndexOutOfBoundsException e) {
			System.out.println(e); //toString
		}
			System.out.println("end");
	}
}
------------------출력------------------
1
2
3
4
5
java.lang.ArrayIndexOutOfBoundsException: Index 5 out of bounds for length 5
end

try-catch를 사용하여 예외처리 된 것을 잡으라고하면 어디서 에러가 났는지 exception부분을 잡아주고 마지막 값까지 나옴.

</code>
  </pre>
  

<code>
  <pre>  
  package exception;

public class ArrayExceptionTest {

	public static void main(String[] args) {
		
		int[] arr = {1, 2, 3, 4, 5};
		try {
		for(int i = 0; i <= 5; i++) {
			System.out.println(arr[i]);
			}
		} catch(ArrayIndexOutOfBoundsException e) {
			System.out.println(e); //toString
			return;
		}finally {    //finally은 try가 수행이 되면 catch다음에 무조건 실행을 하기때문에 "fianlly"이 출력된다.
			System.out.println("finally");
		}
			System.out.println("end");
	}
}

-----------------출력-----------------
1
2
3
4
5
java.lang.ArrayIndexOutOfBoundsException: Index 5 out of bounds for length 5
finally

end에 도착하기 전에 return을 해서 e에 해당하는 exception부분만 출력됐지만,
finally는 try가 수행되면 무조건 출력되기 때문에 finally가 출력 됨.
</code>
  </pre>
  
<code>
  <pre>
  
 package exception;

import java.io.FileInputStream;
import java.io.FileNotFoundException;
import java.io.IOException;

public class ExceptionTest {

	public static void main(String[] args) {
		
		FileInputStream fis = null;
		
		try {
			fis = new FileInputStream("a.txt");
		} catch (FileNotFoundException e) {
			System.out.println(e);
		} finally {
			try {
				fis.close();
			} catch (IOException e) {   //있지도 않은 파일 닫으라고해서 오류남.
				e.printStackTrace();
			}
			System.out.println("finally");
		}
		System.out.println("end");

	}

}
-----------------출력-----------------
java.io.FileNotFoundException: a.txt (지정된 파일을 찾을 수 없습니다)
Exception in thread "main" java.lang.NullPointerException: Cannot invoke "java.io.FileInputStream.close()" because "fis" is null
	at Chapter14/exception.ExceptionTest.main(ExceptionTest.java:19)
  
a.text 파일이 없어서 파일 찾을 수 없다고 함.  
a.text 파일 생성해주면 finally와 end 다 출력됨.
  

</code>
  </pre>
  
## try - with - resources 문
- try-catch-finally까지 사용하면 코드가 너무 지져분해져서 쓰임.
- 리소스를 자동 해제 하도록 제공해주는 구문. (try-catch-finally는 finally를 사용하여 직접 실행 종료를 해줘야 했음.)
- close()를 명시적으로 호출하지 않아도 try{} 블록에서 열린 리소스는 정상적인 경우, 예외 발생한 경우 모두 자동 해제 됨.
- 해당 리소스가 AutoCloseable을 구현 해야 함.
- FileInputStream 의 경우 AutoCloseable을 구현 하고 있음.
  
<code>
  <pre>
package exception;

public class AutoCloseObj implements AutoCloseable{ //AutoCloseable을 쓰면 

	@Override
	public void close() throws Exception {      //자동으로 닫아주는 매서드가 생김
		System.out.println("close()");
		
	}
}



package exception;

public class AutoCloseTest {

	public static void main(String[] args) {
		
		try(AutoCloseObj obj = new AutoCloseObj()){
		} catch(Exception e) {
			System.out.println("exception");
			
		}
		
		
		/*try(AutoCloseObj obj = new AutoCloseObj()) {
		}catch(Exception e) {
			System.out.println("exception");*/
		}
	}

-------------------출력-------------------
close()


오류가 난 부분이 없기때문에 close()를 출력하고 AutoCloseable에 의해 자동으로 종료됨.
만약 오류가 났으면 catch에 있는 exception이 출력됐을거임.
</code>
  </pre>

  
## throw : 예외를 강제로 발생시킴.
<code>
  <pre>
  package exception;

public class AutoCloseObj implements AutoCloseable{

	@Override
	public void close() throws Exception {
		System.out.println("close()");
	}
}




package exception;

public class AutoCloseTest {

	public static void main(String[] args) {
		
		try(AutoCloseObj obj = new AutoCloseObj()){
			throw new Exception();    //throw 예외를 강제적으로 발생시키라는 말.
		} catch(Exception e) {
			System.out.println("exception");
			
		}
	}
}
-------------------출력-------------------
close()
exception

throw로 인해 exception이 강제로 발생해서
정상적으로 나온 close() 먼저 출력 후에 exception


## throws : 예외를 미룸.

<code>
  <pre>
  package exception;

import java.io.FileInputStream;
import java.io.FileNotFoundException;

public class ThrowsException {

	public Class loadClass(String fileName, String className) throws FileNotFoundException, ClassNotFoundException {  //여기서 예외를 throws로 미루면
		FileInputStream fis = new FileInputStream(fileName);
		Class c = Class.forName(className);
		return c;
	}
	
  
  
	public static void main(String[] args) {    
		ThrowsException ex = new ThrowsException();   //미룬 것에 대해 try - catch로 수행하라는 에러가 뜬다.
		try {
			ex.loadClass("b.txt", "java.lang.string");    //try - catch로 수행했지만 File과 Class를 찾을 수 없으니 
		} catch (FileNotFoundException e) {             //파일을 찾을 수 없다는 출력이 나온다.
			System.out.println(e);
		} catch (ClassNotFoundException e) {
			System.out.println(e);
		}
	
		System.out.println("end");  //중간에 죽은건 아니고 exception이 떨어지고 끝이 난거기때문에 end도 출력됨.
	}
}

-------------------출력-------------------
java.io.FileNotFoundException: b.txt (지정된 파일을 찾을 수 없습니다)
end

</code>
  </pre>


<code>
  <pre>
  package exception;

import java.io.FileInputStream;
import java.io.FileNotFoundException;

public class ThrowsException {

	public Class loadClass(String fileName, String className) throws FileNotFoundException, ClassNotFoundException {
		FileInputStream fis = new FileInputStream(fileName);
		Class c = Class.forName(className);
		return c;
	}
	
	public static void main(String[] args) {

		
		ThrowsException ex = new ThrowsException();
		try {
			ex.loadClass("b.txt", "java.lang.String");
		} catch (FileNotFoundException e) {
			System.out.println(e);
		} catch (ClassNotFoundException e) {
			System.out.println(e);
		} catch (Exception e) {   //어떤 exception이 발생할지 모르겠다하면 이렇게 디폴트로 놔주면 됨. 
      System.out.println(e);   //이걸 맨 위에 써주면 안됨. exception은 최상위 클래스이기 때문에 모든 exception이 상위 클래스로 업캐스팅 될 수 있어서
                                //디폴트에서 모든 exception이 handling 될 수 있음. 그래서 디폴트 exception은 맨 마지막에 써야됨.	 
		System.out.println("end");
	}
}
-------------------출력-------------------
end

파일 만들어주고 java.lang.String으로 바꿔주면 정상작동함.


</code>
  </pre>
  
  
## 사용자 정의 예외 클래스
- exception을 직접 만들어서 어떤 상황에 issue 시키면 됨.

<code>
  <pre>
  package exception;

public class IDFormatException extends Exception{
	
	public IDFormatException(String message) {
		super(message);
	}

}




package exception;

public class IDFormatTest {
	
	private String userID;
	
	public String getUserID() {
		return userID;
	}

	public void setUserID(String userID) throws IDFormatException {
		
		if(userID == null) {
			throw new IDFormatException("아이디는 null 일 수 없습니다.");
		}
		else if(userID.length() < 8 || userID.length() > 20) {
			throw new IDFormatException("아이디는 8자 이상 20자 이하로 쓰세요.");

		}
		this.userID = userID;
	}
 
	public static void main(String[] args) {

		IDFormatTest idTest = new IDFormatTest();
		String userID = null;
		
		try {
			idTest.setUserID(userID);
		} catch (IDFormatException e) {
			System.out.println(e);
		}
	
		userID = "1234567";
		try {
			idTest.setUserID(userID);
		} catch (IDFormatException e) {
			System.out.println(e);
		}
	}
}

-------------------출력-------------------
exception.IDFormatException: 아이디는 null 일 수 없습니다.
exception.IDFormatException: 아이디는 8자 이상 20자 이하로 쓰세요.


</code>
  </pre>
  
